<testsuite errors="0" failures="2" name="" tests="3">
<testcase classname="aaa.dd" name="test_CheckType" />
<testcase classname="aaa.cc" name="test_CheckOther"><failure></failure></testcase>
<testcase classname="aaa.bbb.ccc" name="test_Data" >
<failure type="AssertionError">Traceback (most recent call last):
  File "foo.py", line 48, in test_Data
    "Please see the log file for details." )
AssertionError: At least one Error encountered. Please see the log file
for details.
</failure>
</testcase>
</testsuite>
